<?xml version="1.0"?>

<robot xmlns:xacro="https://www.ros.org/wiki/xacro" name="slam_nav2_bot" >

    <xacro:include filename="bot_gz_harmonic.xacro"/>
    <xacro:include filename="lidar.xacro"/>
    <xacro:include filename="camera.xacro"/> 
    <xacro:include filename="imu.xacro"/> 


    <material name="white">
        <color rgba="1 1 1 1"/>
    </material>
      
      <!-- Green color -->
    <material name="Green">
        <color rgba="0 1 0 1"/>
    </material>
      
      <!-- Blue color -->
    <material name="black">
        <color rgba="0 0 0 1"/>
    </material>
      
      <!-- Yellow color -->
    <material name="Yellow">
        <color rgba="1 1 0 1"/>
    </material>

    <!-- BASE FOOTPRINT LINK -->
    <link name="base_footprint">
    </link>

<!-- BASE LINK -->
    <joint name="base_link_joint" type="fixed">
        <parent link="base_footprint"/>
        <child link="base_link"/>
        <origin xyz="0 0 0.016" rpy="0 0 4.7124"/>
    </joint>

    <link name="base_link">
        <visual>
            <origin xyz="0 0 0" rpy="0 0 0"/>
            <geometry>
               <mesh filename="file://$(find slam_nav2_bot)/meshes/base_llink.stl" scale="0.001 0.001 0.001"/> 
            </geometry>
            <material name="Green"/>
        </visual>
        <collision>
            <origin xyz="0 0 0" rpy="0 0 0"/>
            <geometry>
               <mesh filename="file://$(find slam_nav2_bot)/meshes/base_llink.stl" scale="0.001 0.001 0.001"/> 
            </geometry>
        </collision>
        <inertial>
            <origin xyz="0 0 0.04" rpy="0.0 0.25 0.3"/>
            <mass value="8.2573504e-01"/>
            <inertia ixx="2.2124416e-02" ixy="-1.2294101e-04" ixz="3.4938785e-04"
                    iyy="2.1193702e-02" iyz="-5.0120904e-05"
                    izz="2.0064271e-02"/>
        </inertial>
    </link>
    <gazebo reference="base_link">
        <material>Gazebo/Green</material>
    </gazebo>

    

<!-- left wheel LINK -->

    <link name="left_wheel_link">
        <visual>
            <origin xyz="0 0 0" rpy="-1.57 0 0"/>
            <geometry>
                <mesh filename="file://$(find slam_nav2_bot)/meshes/wheel_left_link.STL"/>
            </geometry>
            <material name="black"/>
        </visual>
        <collision>
            <origin xyz="0 0.015 0" rpy="-1.57 0 0"/>
            <geometry>
                <cylinder length="0.03" radius="0.033"/>
            </geometry>
        </collision>
        <inertial>
            <origin xyz="0 0.014 0" rpy="0 0 0"/>
            <mass value="0.0530086090966721"/>
            <inertia ixx="1.88176298336665E-05" ixy="-4.8444933029987E-10" ixz="1.88163708851143E-08" 
                    iyy="3.11510738647764E-05" iyz="-6.93560663069607E-11" 
                    izz="1.8801969558182E-05"/>
        </inertial>
    </link>

    <gazebo reference="left_wheel_link">
        <material>Gazebo/Black</material>
    </gazebo>

    <joint name="left_wheel_joint" type="continuous">
        <parent link="base_link"/>
        <child link="left_wheel_link"/>
        <axis xyz="0 1 0"/>
        <origin xyz="0.101 0 0.016" rpy="0 0 -1.57"/>
    </joint>
<!-- Right wheel LINK -->

    <link name="right_wheel_link">
        <visual>
            <origin xyz="0 0 0" rpy="1.57 0 0"/>
            <geometry>
                <mesh filename="file://$(find slam_nav2_bot)/meshes/wheel_right_link.STL" />
            </geometry>
            <material name="black"/>
        </visual>
        <collision>
            <origin xyz="0 -0.015 0" rpy="1.57 0 0"/>
            <geometry>
                <cylinder length="0.03" radius="0.033"/>
            </geometry>
        </collision>
        <inertial>
            <origin xyz="0 -0.014 0" rpy="0 0 0"/>
            <mass value="0.0530086090966721"/>
            <inertia ixx="1.88176298336665E-05" ixy="-4.8444933029987E-10" ixz="1.88163708851143E-08" 
                    iyy="3.11510738647764E-05" iyz="-6.93560663069607E-11" 
                    izz="1.8801969558182E-05"/>
        </inertial>
    </link>

    <gazebo reference="right_wheel_link">
        <material>Gazebo/Black</material>
    </gazebo>

    <joint name="right_wheel_joint" type="continuous">
        <parent link="base_link"/>
        <child link="right_wheel_link"/>
        <axis xyz="0 1 0"/>
        <origin xyz="-0.101 0 0.016" rpy="0 0 -1.57"/>
    </joint>

<!-- Caster front wheel LINK -->

    <link name="front_caster_link">
        <visual>
            <origin xyz="0 0 0" rpy="0 0 1.57"/>
            <geometry>
               <mesh filename="file://$(find slam_nav2_bot)/meshes/caster_front_link.STL" scale="2 2 2"/>
            </geometry>
            <material name="white"/>
        </visual>
        <collision>
            <origin xyz="0 0 0" rpy="0 0 1.57"/>
            <geometry>
               <mesh filename="file://$(find slam_nav2_bot)/meshes/caster_front_link.STL" scale="2 2 2"/>
            </geometry>
        </collision>
        <inertial>
            <origin xyz="3.89968128948481E-07 2.40073004698083E-07 0.00219173397061506" rpy="0 0 0"/>
            <mass value="1.44379265037903E-06"/>
            <inertia ixx="7.23075276010246E-11" ixy="-6.10956883467859E-16" ixz="2.22849693525031E-15" 
                    iyy="3.8713793085917E-11" iyz="2.93909858781952E-15" 
                    izz="1.00967486676306E-10"/>
        </inertial>
    </link>
    <gazebo reference="front_caster_link">
        <material>Gazebo/White</material>
    </gazebo>

    <joint name="front_caster_joint" type="fixed">
        <parent link="base_link"/>
        <child link="front_caster_link"/>
        <origin xyz="0 -0.08 -0.0065" rpy="0 0 0"/>
    </joint>

<!-- Caster Rear wheel LINK -->

    <link name="rear_caster_link">
        <visual>
            <origin xyz="0 0 0" rpy="0 0 1.57"/>
            <geometry>
           <mesh filename="file://$(find slam_nav2_bot)/meshes/caster_front_link.STL" scale="2 2 2"/>
            </geometry>
            <material name="white"/>
        </visual>
        <collision>
            <origin xyz="0 0 0" rpy="0 0 1.57"/>
            <geometry>
           <mesh filename="file://$(find slam_nav2_bot)/meshes/caster_front_link.STL" scale="2 2 2"/>
            </geometry>
        </collision>
        <inertial>
            <origin xyz="3.8996812895542E-07 2.40073004698083E-07 0.00219173397061509" rpy="0 0 0"/>
            <mass value="1.44379265037902E-06"/>
            <inertia ixx="7.23075276010246E-11" ixy="-6.10956872363424E-16" ixz="2.22849693527207E-15" 
                    iyy="3.87137930859167E-11" iyz="2.939098587861E-15" 
                    izz="1.00967486676306E-10"/>
        </inertial>
    </link>
    <gazebo reference="rear_caster_link">
        <material>Gazebo/White</material>
    </gazebo>

    <joint name="rear_caster_joint" type="fixed">
        <parent link="base_link"/>
        <child link="rear_caster_link"/>
        <origin xyz="0 0.08 -0.0065" rpy="0 0 0"/>
    </joint>

</robot>    